Workbook

Sheet 凡例
A1: 近代日本文学コーパス（JLit）メタデータ v2
A3: 作成日: 2026-09-20 ／ 対象: DH_text_analytics_2025/corpus の全64ファイル
A5: ■ このブックの目的
A6: v1（コーパスdescription.xlsx）の year・ndc・genre・comments・brow の5列を，典拠にもとづいて全面的に
A7: 作り直したもの。あわせて，テクスト本体の診断で見つかった問題を記録する。
A9: ■ 最重要の3点
A10: (1) 乱歩_灰色の巨人.txt の本文は『魔法博士』と同一である。8-gram 一致率45.3%，冒頭は完全一致，
A11: 章題も同一（動く映画館／悪魔の国／人造人間／黄金怪人／…）。『灰色の巨人』は事実上未収録であり，
A12: 実効サンプル数は 64 ではなく 63 である。
A13: (2) 本文中に ※ が計592箇所残存している。これは青空文庫の外字注記 ※［＃…］ から［＃…］だけを
A14: 削除した結果であり，文字そのものが失われている（例：不如帰「合※の式」← 合巹の式）。
A15: 最多は鴎外『伊沢蘭軒』166箇所，海野十三『敗戦日記』110箇所，宮本百合子『道標』86箇所。
... A31: 再構築後は scripts/00_build_metadata_v2.py を再実行して更新すること。

Sheet metadata_v2
A1: id | B1: file_v1 | C1: author_ja | D1: author_reading | E1: author_sex | F1: author_birth | G1: author_death | H1: title_aozora | I1: aozora_person_id | J1: aozora_work_id | K1: aozora_card_url | L1: year_first | M1: year_first_end | N1: year_source | O1: period | P1: ndc | Q1: ndc_label | R1: genre_main | S1: genre_sub | T1: form | U1: audience | V1: register_level | W1: narration | X1: first_medium | Y1: kana_orthography | Z1: completeness | AA1: note | AB1: tokens | AC1: types | AD1: ttr_x1000 | AE1: kanji_ratio | AF1: katakana_ratio | AG1: bungo_per10k | AH1: kogo_per10k | AI1: p1_per10k | AJ1: p3_per10k | AK1: gaiji_lost | AL1: kana_odoriji | AM1: kanji_odoriji | AN1: ditto_mark | AO1: latin_chars | AP1: arabic_digits | AQ1: style_class
A2: JLIT001 | B2: 中島敦_光と風と夢.txt | C2: 中島敦 | D2: なかじま あつし | E2: M | F2: 1909 | G2: 1942 | H2: 光と風と夢 | I2: 000119 | J2: 1743 | K2: https://www.aozora.gr.jp/cards/000119/card1743.html | L2: 1942 | M2: 1942 | N2: editor | O2: 5_昭和戦前(1926-1944) | P2: 913 | Q2: 日本文学／小説・物語 | R2: Fiction | S2: Historical | T2: novel | U2: general | V2: canonical | W2: mixed | X2: magazine | Y2: 新字新仮名 | Z2: complete | AA2: 初出『文學界』1942年5月。カードに初出欄なし | AB2: 50346 | AC2: 7266 | AD2: 144.32 | AE2: 0.3514 | AF2: 0.0838 | AG2: 25.2 | AH2: 15.3 | AI2: 91.8 | AJ2: 44.5 | AK2: 0 | AL2: 0 | AM2: 196 | AN2: 0 | AO2: 235 | AP2: 0 | AQ2: B_過渡的文体
A3: JLIT002 | B3: 乱歩_宇宙怪人.txt | C3: 江戸川乱歩 | D3: えどがわ らんぽ | E3: M | F3: 1894 | G3: 1965 | H3: 宇宙怪人 | I3: 001779 | J3: 56674 | K3: https://www.aozora.gr.jp/cards/001779/card56674.html | L3: 1953 | M3: 1953 | N3: card | O3: 6_昭和戦後(1945-) | P3: K913 | Q3: 児童書／日本の小説・物語 | R3: Fiction | S3: Juvenile-Mystery | T3: novel | U3: juvenile | V3: popular | W3: third | X3: magazine | Y3: 新字新仮名 | Z3: complete | AA3: 「少年」1953年1〜12月号 | AB3: 53728 | AC3: 3959 | AD3: 73.69 | AE3: 0.138 | AF3: 0.0486 | AG3: 14 | AH3: 212.2 | AI3: 13.6 | AJ3: 1.1 | AK3: 0 | AL3: 0 | AM3: 36 | AN3: 0 | AO3: 0 | AP3: 0 | AQ3: C_口語体
A4: JLIT003 | B4: 乱歩_少年探偵団.txt | C4: 江戸川乱歩 | D4: えどがわ らんぽ | E4: M | F4: 1894 | G4: 1965 | H4: 少年探偵団 | I4: 001779 | J4: 56669 | K4: https://www.aozora.gr.jp/cards/001779/card56669.html | L4: 1937 | M4: 1937 | N4: card | O4: 5_昭和戦前(1926-1944) | P4: K913 | Q4: 児童書／日本の小説・物語 | R4: Fiction | S4: Juvenile-Mystery | T4: novel | U4: juvenile | V4: popular | W4: third | X4: magazine | Y4: 新字新仮名 | Z4: complete | AA4: 「少年倶楽部」1937年1〜12月号 | AB4: 59938 | AC4: 4946 | AD4: 82.52 | AE4: 0.175 | AF4: 0.024 | AG4: 17.4 | AH4: 227.4 | AI4: 18.7 | AJ4: 2.7 | AK4: 0 | AL4: 0 | AM4: 30 | AN4: 0 | AO4: 32 | AP4: 5 | AQ4: C_口語体
A5: JLIT004 | B5: 乱歩_灰色の巨人.txt | C5: 江戸川乱歩 | D5: えどがわ らんぽ | E5: M | F5: 1894 | G5: 1965 | H5: 灰色の巨人 | I5: 001779 | J5: 56676 | K5: https://www.aozora.gr.jp/cards/001779/card56676.html | L5: 1955 | M5: 1955 | N5: card | O5: 6_昭和戦後(1945-) | P5: K913 | Q5: 児童書／日本の小説・物語 | R5: Fiction | S5: Juvenile-Mystery | T5: novel | U5: juvenile | V5: popular | W5: third | X5: magazine | Y5: 新字新仮名 | Z5: DUPLICATE | AA5: 【重大】当該ファイルの本文は『魔法博士』と同一。『灰色の巨人』は未収録。要再取得 | AB5: 46258 | AC5: 3205 | AD5: 69.29 | AE5: 0.1443 | AF5: 0.0415 | AG5: 13.8 | AH5: 216 | AI5: 19.9 | AJ5: 0.6 | AK5: 0 | AL5: 0 | AM5: 6 | AN5: 0 | AO5: 30 | AP5: 0 | AQ5: C_口語体
A6: JLIT005 | B6: 乱歩_魔法博士.txt | C6: 江戸川乱歩 | D6: えどがわ らんぽ | E6: M | F6: 1894 | G6: 1965 | H6: 魔法博士 | I6: 001779 | J6: 56679 | K6: https://www.aozora.gr.jp/cards/001779/card56679.html | L6: 1956 | M6: 1956 | N6: card | O6: 6_昭和戦後(1945-) | P6: K913 | Q6: 児童書／日本の小説・物語 | R6: Fiction | S6: Juvenile-Mystery | T6: novel | U6: juvenile | V6: popular | W6: third | X6: magazine | Y6: 新字新仮名 | Z6: complete | AA6: 「少年」1956年1〜12月号 | AB6: 46152 | AC6: 3204 | AD6: 69.42 | AE6: 0.1443 | AF6: 0.0414 | AG6: 13.9 | AH6: 216.5 | AI6: 19.9 | AJ6: 0.7 | AK6: 0 | AL6: 0 | AM6: 6 | AN6: 0 | AO6: 30 | AP6: 0 | AQ6: C_口語体
A7: JLIT006 | B7: 啄木_鳥影.txt | C7: 石川啄木 | D7: いしかわ たくぼく | E7: M | F7: 1886 | G7: 1912 | H7: 鳥影 | I7: 000153 | J7: 46947 | K7: https://www.aozora.gr.jp/cards/000153/card46947.html | L7: 1908 | M7: 1908 | N7: card | O7: 3_明治後期(1900-1911) | P7: 913 | Q7: 日本文学／小説・物語 | R7: Fiction | S7: Naturalist | T7: novel | U7: general | V7: canonical | W7: third | X7: newspaper | Y7: 新字旧仮名 | Z7: complete | AA7: 「東京毎日新聞」1908年11〜12月。旧仮名・仮名踊り字を含む | AB7: 60529 | AC7: 5985 | AD7: 98.88 | AE7: 0.3676 | AF7: 0.0234 | AG7: 11.9 | AH7: 65.9 | AI7: 43.5 | AJ7: 6.8 | AK7: 10 | AL7: 75 | AM7: 147 | AN7: 0 | AO7: 43 | AP7: 0 | AQ7: C_口語体
A8: JLIT007 | B8: 坂口安吾_JIRORIの女.txt | C8: 坂口安吾 | D8: さかぐち あんご | E8: M | F8: 1906 | G8: 1955 | H8: ジロリの女 | I8: 001095 | J8: 42827 | K8: https://www.aozora.gr.jp/cards/001095/card42827.html | L8: 1948 | M8: 1948 | N8: card | O8: 6_昭和戦後(1945-) | P8: 913 | Q8: 日本文学／小説・物語 | R8: Fiction | S8: Modern | T8: novella | U8: general | V8: canonical | W8: first | X8: magazine | Y8: 新字新仮名 | Z8: complete | AA8: ファイル名の 'JIRORI' はローマ字化。正題は「ジロリの女」 | AB8: 31495 | AC8: 4433 | AD8: 140.75 | AE8: 0.2396 | AF8: 0.0587 | AG8: 23.5 | AH8: 138.8 | AI8: 218.1 | AJ8: 6.4 | AK8: 0 | AL8: 0 | AM8: 74 | AN8: 0 | AO8: 1 | AP8: 0 | AQ8: C_口語体
A9: JLIT008 | B9: 坂口安吾_不連続殺人.txt | C9: 坂口安吾 | D9: さかぐち あんご | E9: M | F9: 1906 | G9: 1955 | H9: 不連続殺人事件 | I9: 001095 | J9: 42626 | K9: https://www.aozora.gr.jp/cards/001095/card42626.html | L9: 1947 | M9: 1948 | N9: card | O9: 6_昭和戦後(1945-) | P9: 913 | Q9: 日本文学／小説・物語 | R9: Fiction | S9: Detective | T9: novel | U9: general | V9: middlebrow | W9: first | X9: magazine | Y9: 新字新仮名 | Z9: complete | AA9: 「日本小説」1947年8月〜1948年8月 | AB9: 99434 | AC9: 8859 | AD9: 89.09 | AE9: 0.2728 | AF9: 0.0516 | AG9: 22.8 | AH9: 161.9 | AI9: 67.9 | AJ9: 11 | AK9: 0 | AL9: 0 | AM9: 316 | AN9: 0 | AO9: 55 | AP9: 1 | AQ9: C_口語体
A10: JLIT009 | B10: 坂口安吾_二流の人.txt | C10: 坂口安吾 | D10: さかぐち あんご | E10: M | F10: 1906 | G10: 1955 | H10: 二流の人 | I10: 001095 | J10: 42919 | K10: https://www.aozora.gr.jp/cards/001095/card42919.html | L10: 1947 | M10: 1947 | N10: card | O10: 6_昭和戦後(1945-) | P10: 913 | Q10: 日本文学／小説・物語 | R10: Fiction | S10: Historical | T10: novella | U10: general | V10: canonical | W10: third | X10: book | Y10: 新字旧仮名 | Z10: complete | AA10: カード記載は九州書房版1947年。雑誌初出（1941「文體」）説あり。v1 の1944は典拠不明 | AB10: 35975 | AC10: 5817 | AD10: 161.7 | AE10: 0.3936 | AF10: 0.0145 | AG10: 27 | AH10: 12.2 | AI10: 29.7 | AJ10: 34.2 | AK10: 0 | AL10: 0 | AM10: 106 | AN10: 0 | AO10: 0 | AP10: 0 | AQ10: B_過渡的文体
A11: JLIT010 | B11: 坂口安吾_復員殺人.txt | C11: 坂口安吾 | D11: さかぐち あんご | E11: M | F11: 1906 | G11: 1955 | H11: 復員殺人事件 | I11: 001095 | J11: 43163 | K11: https://www.aozora.gr.jp/cards/001095/card43163.html | L11: 1949 | M11: 1950 | N11: card | O11: 6_昭和戦後(1945-) | P11: 913 | Q11: 日本文学／小説・物語 | R11: Fiction | S11: Detective | T11: novel | U11: general | V11: middlebrow | W11: first | X11: magazine | Y11: 新字新仮名 | Z11: incomplete | AA11: 「座談」1949〜1950年、未完 | AB11: 60197 | AC11: 6077 | AD11: 100.95 | AE11: 0.2695 | AF11: 0.053 | AG11: 28.7 | AH11: 179.2 | AI11: 45.8 | AJ11: 18.4 | AK11: 1 | AL11: 0 | AM11: 111 | AN11: 0 | AO11: 0 | AP11: 0 | AQ11: C_口語体
A12: JLIT011 | B12: 坂口安吾_金銭無情.txt | C12: 坂口安吾 | D12: さかぐち あんご | E12: M | F12: 1906 | G12: 1955 | H12: 金銭無情 | I12: 001095 | J12: 42866 | K12: https://www.aozora.gr.jp/cards/001095/card42866.html | L12: 1947 | M12: 1947 | N12: card | O12: 6_昭和戦後(1945-) | P12: 913 | Q12: 日本文学／小説・物語 | R12: Fiction | S12: Modern | T12: cycle | U12: general | V12: canonical | W12: third | X12: magazine | Y12: 新字旧仮名 | Z12: complete | AA12: 「金銭無情」「失恋難」「夜の王様」「王様失脚」4篇の連作。v1 の 'Experimental?' を改める | AB12: 49097 | AC12: 6146 | AD12: 125.18 | AE12: 0.255 | AF12: 0.0705 | AG12: 29.5 | AH12: 67.4 | AI12: 51.1 | AJ12: 22.4 | AK12: 0 | AL12: 1 | AM12: 79 | AN12: 0 | AO12: 8 | AP12: 0 | AQ12: C_口語体
A13: JLIT012 | B13: 壷井栄_二十四の瞳.txt | C13: 壺井栄 | D13: つぼい さかえ | E13: F | F13: 1899 | G13: 1967 | H13: 二十四の瞳 | I13: 001875 | J13: 57856 | K13: https://www.aozora.gr.jp/cards/001875/card57856.html | L13: 1952 | M13: 1952 | N13: card | O13: 6_昭和戦後(1945-) | P13: 913 | Q13: 日本文学／小説・物語 | R13: Fiction | S13: Modern | T13: novel | U13: general | V13: middlebrow | W13: third | X13: magazine | Y13: 新字新仮名 | Z13: complete | AA13: ファイル名の「壷」は正字「壺」 | AB13: 67800 | AC13: 6455 | AD13: 95.21 | AE13: 0.1826 | AF13: 0.022 | AG13: 19.6 | AH13: 76.8 | AI13: 14 | AJ13: 17.3 | AK13: 0 | AL13: 0 | AM13: 21 | AN13: 0 | AO13: 4 | AP13: 0 | AQ13: C_口語体
... A65: JLIT064 | B65: 鴎外_青年.txt | C65: 森鴎外 | D65: もり おうがい | E65: M | F65: 1862 | G65: 1922 | H65: 青年 | I65: 000129 | J65: 2522 | K65: https://www.aozora.gr.jp/cards/000129/card2522.html | L65: 1910 | M65: 1911 | N65: card | O65: 3_明治後期(1900-1911) | P65: 913 | Q65: 日本文学／小説・物語 | R65: Fiction | S65: Bildungsroman | T65: novel | U65: general | V65: canonical | W65: third | X65: magazine | Y65: 新字新仮名 | Z65: complete | AA65: 【修正】「昴」1910年3月〜1911年8月。v1 の1910は開始年のみ。ラテン文字1895字（独語） | AB65: 79931 | AC65: 7656 | AD65: 95.78 | AE65: 0.3091 | AF65: 0.0102 | AG65: 11.5 | AH65: 54.8 | AI65: 33.7 | AJ65: 1.6 | AK65: 2 | AL65: 0 | AM65: 114 | AN65: 0 | AO65: 1895 | AP65: 0 | AQ65: C_口語体

Sheet changes_from_v1
A1: id | B1: 列 | C1: v1の値 | D1: v2の値 | E1: 変更の種類 | F1: 典拠
A2: JLIT028 | B2: year | C2: 1977 | D2: 1935 | E2: 誤り（底本刊年を初出年としていた） | F2: 青空文庫 図書カード card43656：初出「新青年」博文館 1935年4〜5月号
A3: JLIT039 | B3: year | C3: 1971 | D3: 1944–1945 | E3: 誤り（初刊年を初出年としていた） | F3: 日記本体の執筆年。1971年は講談社版の刊年
A4: JLIT025 | B4: year | C4: 1927 | D4: 1924–1926 | E4: 誤り（単行本年を初出年としていた） | F4: 青空文庫 図書カード card2015：「改造」1924年9月〜1926年9月号
A5: JLIT056 | B5: year | C5: 1935 | D5: 1929–1935 | E5: 不正確（完結年のみ） | F5: 「中央公論」連載期間
A6: JLIT058 | B6: year | C6: 1919 | D6: 1918–1919 | E6: 不正確（完結年のみ） | F6: 青空文庫 図書カード card843：「東京朝日新聞」1918年5月1日〜1919年10月24日
A7: JLIT064 | B7: year | C7: 1910 | D7: 1910–1911 | E7: 不正確（開始年のみ） | F7: 青空文庫 図書カード card2522：「昴」1910年3月〜1911年8月
A8: JLIT052 | B8: year | C8: 1913 | D8: 1912–1913 | E8: 不正確（完結年のみ） | F8: 青空文庫 図書カード card49682：「やまと新聞」1912年11月13日〜1913年1月21日
A9: JLIT049 | B9: year | C9: 1917 | D9: 1936（要確認） | E9: 誤り（シリーズ開始年を個別話の年としていた） | F9: 1917年は半七捕物帳シリーズ全体の開始年。第69話「白蝶怪」は後期作
A10: JLIT034 | B10: year | C10: 1898 | D10: 1898–1899 | E10: 不正確 | F10: 「國民新聞」連載期間
A11: JLIT026 | B11: year | C11: 1947 | D11: 1946–1947 | E11: 不正確 | F11: 「新日本文学」創刊号（1946年3月）が初出
A12: JLIT009 | B12: year | C12: 1944 | D12: 1947（典拠なし） | E12: 典拠不明 | F12: 青空文庫カードは九州書房版1947年1月30日。v1の1944の根拠が不明
A13: JLIT036 | B13: year | C13: 1930 | D13: 1928–1930（初出）／1949（本文の版） | E13: 概念の混同 | F13: 初出年と底本テクストの成立年を分離した
A14: ALL | B14: ndc | C14: 「小説、物語」等のラベル文字列 | D14: 913 / K913 / 914 / 915 / 289 / 370 / 180 | E14: データ型の誤り | F14: 青空文庫の分類欄は NDC 番号を持つ。ラベルは ndc_label 列に分離
A15: JLIT031 | B15: ndc | C15: 「自己啓発？」 | D15: 180（仏教） | E15: 分類の誤り | F15: 青空文庫 図書カード card52342：NDC 180
A16: JLIT046 | B16: ndc | C16: 「教育」 | D16: 370（教育） | E16: ラベル→番号 | F16: 青空文庫 図書カード card47061：NDC 370
A17: JLIT047 | B17: ndc | C17: 「個人伝記」 | D17: 289（個人伝記） | E17: ラベル→番号 | F17: 青空文庫 図書カード card1864：NDC 289
A18: JLIT054 | B18: ndc | C18: 「評論、エッセイ、随筆」 | D18: 914 | E18: ラベル→番号 | F18: 青空文庫 図書カード card26：NDC 914
A19: JLIT055 | B19: ndc | C19: 「評論、エッセイ、随筆」 | D19: 914 | E19: ラベル→番号 | F19: 青空文庫 図書カード card1503：NDC 914
A20: JLIT039 | B20: ndc | C20: 「日記、書簡、紀行」 | D20: 915 | E20: ラベル→番号 | F20: 青空文庫 図書カード card1255：NDC 915
A21: 児童書7件 | B21: ndc | C21: 「小説、物語 (児童書)」 | D21: K913 | E21: ラベル→番号 | F21: 青空文庫は児童書に K 接頭辞付き NDC を与える
A22: ALL | B22: genre | C22: 英語ラベル・日本語ラベル・別題・誤綴の混在 | D22: genre_main / genre_sub の2層統制語彙 | E22: 語彙統制 | F22: 'Histrical novel'（誤綴）, '（二十世紀鉄仮面）'（別題）, '怪奇'（日本語）等を整理
A23: JLIT011 | B23: genre | C23: Experimental? | D23: Fiction / Modern（form=cycle） | E23: 分類の誤り | F23: 「金銭無情」「失恋難」「夜の王様」「王様失脚」4篇の連作。実験小説ではない
A24: JLIT023 | B24: genre | C24: 超現実主義的 | D24: Fiction / Experimental（narration=dialogue） | E24: 記述の精密化 | F24: 全篇対話体である点を narration 列で表現
A25: JLIT028 | B25: genre | C25: （二十世紀鉄仮面） | D25: Fiction / Detective | E25: 別題の混入 | F25: 「二十世紀鉄仮面」は改題。genre 列に入るべきものではない
A26: JLIT013 | B26: genre | C26: 小説、物語 | D26: Fiction / Modern | E26: ndc ラベルの混入 | F26: genre 列に NDC ラベルが入っていた
A27: JLIT061/62/63 | B27: genre | C27: Histrical novel | D27: Fiction|Nonfiction / Historical(-Biography) | E27: 誤綴の訂正と再分類 | F27: 『伊沢蘭軒』『渋江抽斎』は史伝＝Nonfiction、『大塩平八郎』は歴史小説
A28: ALL | B28: comments | C28: 語り・叢書形態・文体注記の混在 | D28: narration / form / style_class / note に分解 | E28: 構造化 | F28: 「現代、独白」→narration=first、「Collection」→form=collection、「Colloquial」→style_class
A29: ALL | B29: brow | C29: high / low の二値 | D29: register_level: canonical / middlebrow / popular / documentary ＋ audience: general / juvenile | E29: 尺度の再設計 | F29: 児童書とノンフィクションが high/low に押し込まれていた
A30: JLIT004 | B30: completeness | C30: — | D30: DUPLICATE | E30: 【重大】本文の取り違え | F30: 乱歩_灰色の巨人.txt の本文は『魔法博士』と同一（8-gram 一致率45.3%、冒頭完全一致）
A31: JLIT004 | B31: completeness | C31: DUPLICATE | D31: complete | E31: 【解消】カード56676から取り直し | F31: 全29章（「志摩の女王」〜「怪人のさいご」）。56679『魔法博士』との文字12-gram 一致率 0.0009
A32: JLIT057 | B32: completeness | C32: — | D32: PARTIAL | E32: 【重大】不完全収録 | F32: 『家』は下巻のみ。上巻（card1509）が欠落
... A34: JLIT056 | B34: completeness | C34: complete | D34: superseded | E34: 二重計上の回避 | F34: v1 の合本。増補で 001504〜001507 を分冊ごとに取り直したので集計から外す

Sheet diagnostics
A1: file | B1: tokens | C1: types | D1: ttr_x1000 | E1: mean_sent_tokens | F1: kanji_ratio | G1: kata_ratio | H1: bungo_per10k | I1: kogo_per10k | J1: p1_per10k | K1: p3_per10k | L1: gaiji_marker | M1: kana_odoriji | N1: kanji_odoriji | O1: ditto_mark | P1: latin_chars | Q1: arabic_digits
A2: 中島敦_光と風と夢.txt | B2: 50346 | C2: 7266 | D2: 144.32 | E2: 19.54 | F2: 0.3514 | G2: 0.0838 | H2: 25.2 | I2: 15.3 | J2: 91.8 | K2: 44.5 | L2: 0 | M2: 0 | N2: 196 | O2: 0 | P2: 235 | Q2: 0
A3: 乱歩_宇宙怪人.txt | B3: 53728 | C3: 3959 | D3: 73.69 | E3: 19.43 | F3: 0.138 | G3: 0.0486 | H3: 14 | I3: 212.2 | J3: 13.6 | K3: 1.1 | L3: 0 | M3: 0 | N3: 36 | O3: 0 | P3: 0 | Q3: 0
A4: 乱歩_少年探偵団.txt | B4: 59938 | C4: 4946 | D4: 82.52 | E4: 20.94 | F4: 0.175 | G4: 0.024 | H4: 17.4 | I4: 227.4 | J4: 18.7 | K4: 2.7 | L4: 0 | M4: 0 | N4: 30 | O4: 0 | P4: 32 | Q4: 5
A5: 乱歩_灰色の巨人.txt | B5: 46258 | C5: 3205 | D5: 69.29 | E5: 17.64 | F5: 0.1443 | G5: 0.0415 | H5: 13.8 | I5: 216 | J5: 19.9 | K5: 0.6 | L5: 0 | M5: 0 | N5: 6 | O5: 0 | P5: 30 | Q5: 0
A6: 乱歩_魔法博士.txt | B6: 46152 | C6: 3204 | D6: 69.42 | E6: 17.6 | F6: 0.1443 | G6: 0.0414 | H6: 13.9 | I6: 216.5 | J6: 19.9 | K6: 0.7 | L6: 0 | M6: 0 | N6: 6 | O6: 0 | P6: 30 | Q6: 0
A7: 啄木_鳥影.txt | B7: 60529 | C7: 5985 | D7: 98.88 | E7: 17.38 | F7: 0.3676 | G7: 0.0234 | H7: 11.9 | I7: 65.9 | J7: 43.5 | K7: 6.8 | L7: 10 | M7: 75 | N7: 147 | O7: 0 | P7: 43 | Q7: 0
A8: 坂口安吾_JIRORIの女.txt | B8: 31495 | C8: 4433 | D8: 140.75 | E8: 21.5 | F8: 0.2396 | G8: 0.0587 | H8: 23.5 | I8: 138.8 | J8: 218.1 | K8: 6.4 | L8: 0 | M8: 0 | N8: 74 | O8: 0 | P8: 1 | Q8: 0
A9: 坂口安吾_不連続殺人.txt | B9: 99434 | C9: 8859 | D9: 89.09 | E9: 19.19 | F9: 0.2728 | G9: 0.0516 | H9: 22.8 | I9: 161.9 | J9: 67.9 | K9: 11 | L9: 0 | M9: 0 | N9: 316 | O9: 0 | P9: 55 | Q9: 1
A10: 坂口安吾_二流の人.txt | B10: 35975 | C10: 5817 | D10: 161.7 | E10: 26.85 | F10: 0.3936 | G10: 0.0145 | H10: 27 | I10: 12.2 | J10: 29.7 | K10: 34.2 | L10: 0 | M10: 0 | N10: 106 | O10: 0 | P10: 0 | Q10: 0
A11: 坂口安吾_復員殺人.txt | B11: 60197 | C11: 6077 | D11: 100.95 | E11: 15.96 | F11: 0.2695 | G11: 0.053 | H11: 28.7 | I11: 179.2 | J11: 45.8 | K11: 18.4 | L11: 1 | M11: 0 | N11: 111 | O11: 0 | P11: 0 | Q11: 0
A12: 坂口安吾_金銭無情.txt | B12: 49097 | C12: 6146 | D12: 125.18 | E12: 22.3 | F12: 0.255 | G12: 0.0705 | H12: 29.5 | I12: 67.4 | J12: 51.1 | K12: 22.4 | L12: 0 | M12: 1 | N12: 79 | O12: 0 | P12: 8 | Q12: 0
A13: 壷井栄_二十四の瞳.txt | B13: 67800 | C13: 6455 | D13: 95.21 | E13: 36.28 | F13: 0.1826 | G13: 0.022 | H13: 19.6 | I13: 76.8 | J13: 14 | K13: 17.3 | L13: 0 | M13: 0 | N13: 21 | O13: 0 | P13: 4 | Q13: 0
... A65: 鴎外_青年.txt | B65: 79931 | C65: 7656 | D65: 95.78 | E65: 21.23 | F65: 0.3091 | G65: 0.0102 | H65: 11.5 | I65: 54.8 | J65: 33.7 | K65: 1.6 | L65: 2 | M65: 0 | N65: 114 | O65: 0 | P65: 1895 | Q65: 0

Sheet representativeness
A1: 代表性の集計（metadata_v2 を COUNTIFS で参照。metadata_v2 を編集すると自動更新される）
A3: 時代区分（period）
A4: 区分 | B4: 作品数 | C4: 構成比 | D4: 延べ語数 | E4: 語数構成比
A5: 1_明治前期(〜1886) | B5: =COUNTIF(metadata_v2!$O$2:$O$65,A5) | C5: =IF($B$11=0,0,B5/$B$11) | D5: =SUMIF(metadata_v2!$O$2:$O$65,A5,metadata_v2!$AB$2:$AB$65) | E5: =IF($D$11=0,0,D5/$D$11)
A6: 2_明治中期(1887-1899) | B6: =COUNTIF(metadata_v2!$O$2:$O$65,A6) | C6: =IF($B$11=0,0,B6/$B$11) | D6: =SUMIF(metadata_v2!$O$2:$O$65,A6,metadata_v2!$AB$2:$AB$65) | E6: =IF($D$11=0,0,D6/$D$11)
A7: 3_明治後期(1900-1911) | B7: =COUNTIF(metadata_v2!$O$2:$O$65,A7) | C7: =IF($B$11=0,0,B7/$B$11) | D7: =SUMIF(metadata_v2!$O$2:$O$65,A7,metadata_v2!$AB$2:$AB$65) | E7: =IF($D$11=0,0,D7/$D$11)
A8: 4_大正(1912-1925) | B8: =COUNTIF(metadata_v2!$O$2:$O$65,A8) | C8: =IF($B$11=0,0,B8/$B$11) | D8: =SUMIF(metadata_v2!$O$2:$O$65,A8,metadata_v2!$AB$2:$AB$65) | E8: =IF($D$11=0,0,D8/$D$11)
A9: 5_昭和戦前(1926-1944) | B9: =COUNTIF(metadata_v2!$O$2:$O$65,A9) | C9: =IF($B$11=0,0,B9/$B$11) | D9: =SUMIF(metadata_v2!$O$2:$O$65,A9,metadata_v2!$AB$2:$AB$65) | E9: =IF($D$11=0,0,D9/$D$11)
A10: 6_昭和戦後(1945-) | B10: =COUNTIF(metadata_v2!$O$2:$O$65,A10) | C10: =IF($B$11=0,0,B10/$B$11) | D10: =SUMIF(metadata_v2!$O$2:$O$65,A10,metadata_v2!$AB$2:$AB$65) | E10: =IF($D$11=0,0,D10/$D$11)
A11: 合計 | B11: =SUM(B5:B10) | D11: =SUM(D5:D10) | G11: 1930年以前の明治期3区分で12点＝全体の19%にすぎない。昭和戦前が26点＝41%を占める。
A13: 文体（style_class）
A14: 区分 | B14: 作品数 | C14: 構成比 | D14: 延べ語数 | E14: 語数構成比
A15: A_文語体 | B15: =COUNTIF(metadata_v2!$AQ$2:$AQ$65,A15) | C15: =IF($B$18=0,0,B15/$B$18) | D15: =SUMIF(metadata_v2!$AQ$2:$AQ$65,A15,metadata_v2!$AB$2:$AB$65) | E15: =IF($D$18=0,0,D15/$D$18)
A16: B_過渡的文体 | B16: =COUNTIF(metadata_v2!$AQ$2:$AQ$65,A16) | C16: =IF($B$18=0,0,B16/$B$18) | D16: =SUMIF(metadata_v2!$AQ$2:$AQ$65,A16,metadata_v2!$AB$2:$AB$65) | E16: =IF($D$18=0,0,D16/$D$18)
A17: C_口語体 | B17: =COUNTIF(metadata_v2!$AQ$2:$AQ$65,A17) | C17: =IF($B$18=0,0,B17/$B$18) | D17: =SUMIF(metadata_v2!$AQ$2:$AQ$65,A17,metadata_v2!$AB$2:$AB$65) | E17: =IF($D$18=0,0,D17/$D$18)
A18: 合計 | B18: =SUM(B15:B17) | D18: =SUM(D15:D17) | G18: 文語体が1点（『学問のすすめ』）のみ。言文一致以前／過渡期の実態を記述できる水準にない。
A20: 仮名遣い（kana_orthography）
A21: 区分 | B21: 作品数 | C21: 構成比 | D21: 延べ語数 | E21: 語数構成比
A22: 新字新仮名 | B22: =COUNTIF(metadata_v2!$Y$2:$Y$65,A22) | C22: =IF($B$25=0,0,B22/$B$25) | D22: =SUMIF(metadata_v2!$Y$2:$Y$65,A22,metadata_v2!$AB$2:$AB$65) | E22: =IF($D$25=0,0,D22/$D$25)
A23: 新字旧仮名 | B23: =COUNTIF(metadata_v2!$Y$2:$Y$65,A23) | C23: =IF($B$25=0,0,B23/$B$25) | D23: =SUMIF(metadata_v2!$Y$2:$Y$65,A23,metadata_v2!$AB$2:$AB$65) | E23: =IF($D$25=0,0,D23/$D$25)
A24: 旧字旧仮名 | B24: =COUNTIF(metadata_v2!$Y$2:$Y$65,A24) | C24: =IF($B$25=0,0,B24/$B$25) | D24: =SUMIF(metadata_v2!$Y$2:$Y$65,A24,metadata_v2!$AB$2:$AB$65) | E24: =IF($D$25=0,0,D24/$D$25)
A25: 合計 | B25: =SUM(B22:B24) | D25: =SUM(D22:D24) | G25: 旧字旧仮名が0点。青空文庫は同一作品に新字／旧字の両版を持つことがあり，選択を統一すべき。
A27: NDC
A28: 区分 | B28: 作品数 | C28: 構成比 | D28: 延べ語数 | E28: 語数構成比
A29: 913 | B29: =COUNTIF(metadata_v2!$P$2:$P$65,A29) | C29: =IF($B$36=0,0,B29/$B$36) | D29: =SUMIF(metadata_v2!$P$2:$P$65,A29,metadata_v2!$AB$2:$AB$65) | E29: =IF($D$36=0,0,D29/$D$36)
A30: K913 | B30: =COUNTIF(metadata_v2!$P$2:$P$65,A30) | C30: =IF($B$36=0,0,B30/$B$36) | D30: =SUMIF(metadata_v2!$P$2:$P$65,A30,metadata_v2!$AB$2:$AB$65) | E30: =IF($D$36=0,0,D30/$D$36)
A31: 914 | B31: =COUNTIF(metadata_v2!$P$2:$P$65,A31) | C31: =IF($B$36=0,0,B31/$B$36) | D31: =SUMIF(metadata_v2!$P$2:$P$65,A31,metadata_v2!$AB$2:$AB$65) | E31: =IF($D$36=0,0,D31/$D$36)
A32: 915 | B32: =COUNTIF(metadata_v2!$P$2:$P$65,A32) | C32: =IF($B$36=0,0,B32/$B$36) | D32: =SUMIF(metadata_v2!$P$2:$P$65,A32,metadata_v2!$AB$2:$AB$65) | E32: =IF($D$36=0,0,D32/$D$36)
A33: 289 | B33: =COUNTIF(metadata_v2!$P$2:$P$65,A33) | C33: =IF($B$36=0,0,B33/$B$36) | D33: =SUMIF(metadata_v2!$P$2:$P$65,A33,metadata_v2!$AB$2:$AB$65) | E33: =IF($D$36=0,0,D33/$D$36)
A34: 370 | B34: =COUNTIF(metadata_v2!$P$2:$P$65,A34) | C34: =IF($B$36=0,0,B34/$B$36) | D34: =SUMIF(metadata_v2!$P$2:$P$65,A34,metadata_v2!$AB$2:$AB$65) | E34: =IF($D$36=0,0,D34/$D$36)
A35: 180 | B35: =COUNTIF(metadata_v2!$P$2:$P$65,A35) | C35: =IF($B$36=0,0,B35/$B$36) | D35: =SUMIF(metadata_v2!$P$2:$P$65,A35,metadata_v2!$AB$2:$AB$65) | E35: =IF($D$36=0,0,D35/$D$36)
A36: 合計 | B36: =SUM(B29:B35) | D36: =SUM(D29:D35) | G36: 913 が51点＝80%。随筆・評論(914)は2点，戯曲(912)・韻文(911)はゼロ。
A38: ジャンル第1層（genre_main）
A39: 区分 | B39: 作品数 | C39: 構成比 | D39: 延べ語数 | E39: 語数構成比
A40: Fiction | B40: =COUNTIF(metadata_v2!$R$2:$R$65,A40) | C40: =IF($B$42=0,0,B40/$B$42) | D40: =SUMIF(metadata_v2!$R$2:$R$65,A40,metadata_v2!$AB$2:$AB$65) | E40: =IF($D$42=0,0,D40/$D$42)
A41: Nonfiction | B41: =COUNTIF(metadata_v2!$R$2:$R$65,A41) | C41: =IF($B$42=0,0,B41/$B$42) | D41: =SUMIF(metadata_v2!$R$2:$R$65,A41,metadata_v2!$AB$2:$AB$65) | E41: =IF($D$42=0,0,D41/$D$42)
A42: 合計 | B42: =SUM(B40:B41) | D42: =SUM(D40:D41)
A44: 読者層（audience）
A45: 区分 | B45: 作品数 | C45: 構成比 | D45: 延べ語数 | E45: 語数構成比
A46: general | B46: =COUNTIF(metadata_v2!$U$2:$U$65,A46) | C46: =IF($B$48=0,0,B46/$B$48) | D46: =SUMIF(metadata_v2!$U$2:$U$65,A46,metadata_v2!$AB$2:$AB$65) | E46: =IF($D$48=0,0,D46/$D$48)
...

Sheet expansion_candidates
A1: priority | B1: gap | C1: author_ja | D1: title | E1: year_target | F1: period_target | G1: ndc_expect | H1: genre_main | I1: genre_sub | J1: style_expect | K1: author_sex | L1: rationale | M1: aozora_status | N1: aozora_work_id | O1: resolution_note | P1: in_corpus
A2: 1 | B2: 明治前期 | C2: ツルゲーネフ イワン | D2: あいびき | E2: 1888 | F2: 2_明治中期(1887-1899) | G2: 983 | H2: Fiction | I2: Translation | J2: 過渡 | K2: M | L2: 二葉亭四迷訳。言文一致の文体実験。青空文庫では原著者の下に登録される | M2: 公開中 | N2: 5 | O2: 著者名はツルゲーネフ イワン。訳者を note に記す | P2: 収録済
A3: 1 | B3: 明治前期 | C3: 二葉亭四迷 | D3: 浮雲 | E3: 1887 | F3: 2_明治中期(1887-1899) | G3: 913 | H3: Fiction | I3: Modern | J3: 過渡 | K3: M | L3: 言文一致体小説の出発点。コーパスの最重要欠落 | M3: 公開中 | O3: — | P3: 収録済
A4: 1 | B4: 明治前期 | C4: 尾崎紅葉 | D4: 金色夜叉 | E4: 1897 | F4: 2_明治中期(1887-1899) | G4: 913 | H4: Fiction | I4: Melodrama | J4: 過渡 | K4: M | L4: 硯友社の雅俗折衷体と新聞小説の大衆性 | M4: 公開中 | O4: — | P4: 収録済
A5: 1 | B5: 明治前期 | C5: 山田美妙 | D5: 武蔵野 | E5: 1887 | F5: 2_明治中期(1887-1899) | G5: 913 | H5: Fiction | I5: Historical | J5: 過渡 | K5: M | L5: 「です・ます」体による言文一致の別系統 | M5: 公開中 | O5: — | P5: 収録済
A6: 1 | B6: 明治前期 | C6: 幸田露伴 | D6: 五重塔 | E6: 1891 | F6: 2_明治中期(1887-1899) | G6: 913 | H6: Fiction | I6: Modern | J6: 文語 | K6: M | L6: 雅俗折衷体。言文一致に抗した側の代表 | M6: 公開中 | O6: — | P6: 収録済
A7: 1 | B7: 明治前期 | C7: 徳冨蘆花 | D7: 良夜 | E7: 1900 | F7: 3_明治後期(1900-1911) | G7: 914 | H7: Nonfiction | I7: Sketch-Essay | J7: 過渡 | K7: M | L7: 『自然と人生』所収の写生文。同書本体は未公開のため所収作で代替 | M7: 公開中 | N7: 46536 | O7: — | P7: 収録済
A8: 1 | B8: 明治前期 | C8: 徳冨蘆花 | D8: 花月の夜 | E8: 1900 | F8: 3_明治後期(1900-1911) | G8: 914 | H8: Nonfiction | I8: Sketch-Essay | J8: 過渡 | K8: M | L8: 同上 | M8: 公開中 | N8: 46537 | O8: — | P8: 収録済
A9: 1 | B9: 明治前期 | C9: 森鴎外 | D9: 舞姫 | E9: 1890 | F9: 2_明治中期(1887-1899) | G9: 913 | H9: Fiction | I9: Modern | J9: 文語 | K9: M | L9: 雅文体。鴎外の文語作品を系列に加える | M9: 公開中 | O9: — | P9: 収録済
A10: 1 | B10: 明治前期 | C10: 正岡子規 | D10: 歌よみに与ふる書 | E10: 1898 | F10: 2_明治中期(1887-1899) | G10: 911 | H10: Nonfiction | I10: Criticism | J10: 文語 | K10: M | L10: 明治期批評文の文語体標本 | M10: 公開中 | O10: — | P10: 収録済
A11: 1 | B11: 明治前期 | C11: 福沢諭吉 | D11: 旧藩情 | E11: 1877 | F11: 1_明治前期(〜1886) | G11: 210 | H11: Nonfiction | I11: Historical-Essay | J11: 文語 | K11: M | L11: 『文明論之概略』の代替。廃藩置県直後の士族社会を論じた明治10年の論説 | M11: 公開中 | N11: 45664 | O11: — | P11: 収録済
A12: 1 | B12: 明治前期 | C12: 福沢諭吉 | D12: 学者安心論 | E12: 1876 | F12: 1_明治前期(〜1886) | G12: 304 | H12: Nonfiction | I12: Enlightenment-Didactic | J12: 文語 | K12: M | L12: 同上。明治9年の論説 | M12: 公開中 | N12: 47054 | O12: — | P12: 収録済
A13: 1 | B13: 明治前期 | C13: 二葉亭四迷 | D13: あひゞき | E13: 1888 | F13: 2_明治中期(1887-1899) | G13: 983 | H13: Fiction | I13: Translation | J13: 過渡 | K13: M | L13: ツルゲーネフ翻訳。言文一致の文体実験として不可欠 | M13: 別著者 | N13: 5 | O13: ツルゲーネフ イワン『あいびき』として公開。NDC 983、二葉亭四迷訳 | P13: 収録済
A14: 1 | B14: 明治前期 | C14: 徳冨蘆花 | D14: 自然と人生 | E14: 1900 | F14: 3_明治後期(1900-1911) | G14: 914 | H14: Nonfiction | I14: Sketch-Essay | J14: 過渡 | K14: M | L14: 1点のみの作家の補強かつ随筆ジャンルの補強 | M14: 作業中 | O14: 未公開。同書所収の写生文『良夜』46536・『花月の夜』46537 で代替 | P14: 未収録
A15: 1 | B15: 明治前期 | C15: 福沢諭吉 | D15: 文明論之概略 | E15: 1875 | F15: 1_明治前期(〜1886) | G15: 304 | H15: Nonfiction | I15: Enlightenment-Didactic | J15: 文語 | K15: M | L15: 明治初期の漢文脈論説文。現行コーパスで1886年以前は『学問のすすめ』1点のみ | M15: 作業中 | O15: 青空文庫で作業中（未公開）。『旧藩情』45664・『学者安心論』47054 で代替 | P15: 未収録
A16: 1 | B16: 明治前期 | C16: 中村正直 | D16: 西国立志編 | E16: 1871 | F16: 1_明治前期(〜1886) | G16: 159 | H16: Nonfiction | I16: Translation-Didactic | J16: 文語 | K16: M | L16: 幕末明治の翻訳文体（漢文訓読体）の基準点 | M16: 未登録 | O16: 作家登録（person2211）はあるが作品は0件。取得不可 | P16: 未収録
A17: 2 | B17: 女性作家 | C17: 与謝野晶子 | D17: 「女らしさ」とは何か | E17: 1921 | F17: 4_大正(1912-1925) | G17: 914 | H17: Nonfiction | I17: Criticism | J17: 口語 | K17: F | L17: 大正期女性評論。『人及び女として』が未公開のための代替 | M17: 公開中 | N17: 3325 | O17: — | P17: 収録済
A18: 2 | B18: 女性作家 | C18: 与謝野晶子 | D18: 私の貞操観 | E18: 1915 | F18: 4_大正(1912-1925) | G18: 914 | H18: Nonfiction | I18: Criticism | J18: 口語 | K18: F | L18: 同上 | M18: 公開中 | N18: 3319 | O18: — | P18: 収録済
A19: 2 | B19: 女性作家 | C19: 伊藤野枝 | D19: 新らしき女の道 | E19: 1913 | F19: 4_大正(1912-1925) | G19: 914 | H19: Nonfiction | I19: Criticism | J19: 口語 | K19: F | L19: 大正期女性評論。1923年没のため公開されている | M19: 公開中 | N19: 56232 | O19: — | P19: 収録済
A20: 2 | B20: 女性作家 | C20: 伊藤野枝 | D20: ある男の堕落 | E20: 1917 | F20: 4_大正(1912-1925) | G20: 913 | H20: Fiction | I20: Modern | J20: 口語 | K20: F | L20: 同上（小説） | M20: 公開中 | N20: 3577 | O20: — | P20: 収録済
A21: 2 | B21: 女性作家 | C21: 樋口一葉 | D21: たけくらべ | E21: 1895 | F21: 2_明治中期(1887-1899) | G21: 913 | H21: Fiction | I21: Modern | J21: 文語 | K21: F | L21: 明治期女性作家の最重要欠落。雅俗折衷体 | M21: 公開中 | O21: — | P21: 収録済
A22: 2 | B22: 女性作家 | C22: 樋口一葉 | D22: にごりえ | E22: 1895 | F22: 2_明治中期(1887-1899) | G22: 913 | H22: Fiction | I22: Modern | J22: 文語 | K22: F | L22: 同上 | M22: 公開中 | O22: — | P22: 収録済
A23: 2 | B23: 女性作家 | C23: 樋口一葉 | D23: 十三夜 | E23: 1895 | F23: 2_明治中期(1887-1899) | G23: 913 | H23: Fiction | I23: Modern | J23: 文語 | K23: F | L23: 同上 | M23: 公開中 | O23: — | P23: 収録済
A24: 2 | B24: 女性作家 | C24: 水野仙子 | D24: 四十余日 | E24: 1913 | F24: 4_大正(1912-1925) | G24: 913 | H24: Fiction | I24: Modern | J24: 口語 | K24: F | L24: 明治末〜大正の女性作家。保護期間の壁を越えられる数少ない例（1919年没） | M24: 公開中 | N24: 601 | O24: — | P24: 収録済
A25: 2 | B25: 女性作家 | C25: 水野仙子 | D25: 脱殻 | E25: 1914 | F25: 4_大正(1912-1925) | G25: 913 | H25: Fiction | I25: Modern | J25: 口語 | K25: F | L25: 同上 | M25: 公開中 | N25: 4263 | O25: — | P25: 収録済
A26: 2 | B26: 女性作家 | C26: 田村俊子 | D26: 木乃伊の口紅 | E26: 1913 | F26: 4_大正(1912-1925) | G26: 913 | H26: Fiction | I26: Modern | J26: 過渡 | K26: F | L26: 田村俊子の唯一の公開作。旧字旧仮名なので正書法の統制に注意 | M26: 公開中 | N26: 5006 | O26: 旧字旧仮名 | P26: 収録済
A27: 2 | B27: 女性作家 | C27: 田村俊子 | D27: あきらめ | E27: 1911 | F27: 3_明治後期(1900-1911) | G27: 913 | H27: Fiction | I27: Modern | J27: 口語 | K27: F | L27: 明治末の女性作家 | M27: 作業中 | O27: 未公開。公開作は『木乃伊の口紅』5006（旧字旧仮名）のみ | P27: 未収録
A28: 2 | B28: 女性作家 | C28: 若松賤子 | D28: 小公子 | E28: 1890 | F28: 2_明治中期(1887-1899) | G28: 933 | H28: Fiction | I28: Translation | J28: 過渡 | K28: F | L28: 女性訳者による言文一致翻訳。ジャンル・性別・文体の三重の空白を同時に埋める | M28: 作業中 | O28: バーネット名義で作業中（作業ID 43033）。未公開 | P28: 未収録
A29: 2 | B29: 女性作家 | C29: 与謝野晶子 | D29: 人及び女として | E29: 1916 | F29: 4_大正(1912-1925) | G29: 914 | H29: Nonfiction | I29: Criticism | J29: 口語 | K29: F | L29: 大正期女性評論の標本 | M29: 未公開 | O29: 公開122作品中になし。『「女らしさ」とは何か』3325・『私の貞操観』3319 で代替 | P29: 未収録
A30: 2 | B30: 女性作家 | C30: 佐多稲子 | D30: キャラメル工場から | E30: 1928 | F30: 5_昭和戦前(1926-1944) | G30: 913 | H30: Fiction | I30: Proletarian | J30: 口語 | K30: F | L30: 同上 | M30: 保護期間中 | O30: 1998年没。2068年まで保護 | P30: 未収録
A31: 2 | B31: 女性作家 | C31: 尾崎翠 | D31: 第七官界彷徨 | E31: 1931 | F31: 5_昭和戦前(1926-1944) | G31: 913 | H31: Fiction | I31: Experimental | J31: 口語 | K31: F | L31: 昭和戦前の実験的女性作家 | M31: 保護期間中 | O31: 1971年没。2018年改正により2041年まで保護 | P31: 未収録
A32: 2 | B32: 女性作家 | C32: 平林たい子 | D32: 施療室にて | E32: 1927 | F32: 5_昭和戦前(1926-1944) | G32: 913 | H32: Fiction | I32: Proletarian | J32: 口語 | K32: F | L32: 女性プロレタリア作家。多喜二4点に対する対照項 | M32: 保護期間中 | O32: 1972年没。2018年改正により2042年まで保護 | P32: 未収録
A33: 2 | B33: 女性作家 | C33: 野上弥生子 | D33: 海神丸 | E33: 1922 | F33: 4_大正(1912-1925) | G33: 913 | H33: Fiction | I33: Modern | J33: 口語 | K33: F | L33: 大正期女性小説。現行コーパスの大正期は10点と手薄 | M33: 保護期間中 | O33: 1985年没。2055年まで保護。青空文庫に登録なし | P33: 未収録
A34: 3 | B34: ジャンル | C34: 上田敏 | D34: 海潮音 | E34: 1905 | F34: 3_明治後期(1900-1911) | G34: 951 | H34: Nonfiction | I34: Translation-Verse | J34: 文語 | K34: M | L34: 訳詩集。韻文の標本（任意） | M34: 公開中 | O34: — | P34: 収録済
A35: 3 | B35: ジャンル | C35: 北村透谷 | D35: 内部生命論 | E35: 1893 | F35: 2_明治中期(1887-1899) | G35: 914 | H35: Nonfiction | I35: Criticism | J35: 文語 | K35: M | L35: 明治期批評文 | M35: 公開中 | O35: — | P35: 収録済
A36: 3 | B36: ジャンル | C36: 寺田寅彦 | D36: 柿の種 | E36: 1933 | F36: 5_昭和戦前(1926-1944) | G36: 914 | H36: Nonfiction | I36: Science-Essay | J36: 口語 | K36: M | L36: 科学随筆。専門語彙の対照群としてトピックモデルに有効 | M36: 公開中 | O36: — | P36: 収録済
A37: 3 | B37: ジャンル | C37: 岡本綺堂 | D37: 修禅寺物語 | E37: 1911 | F37: 3_明治後期(1900-1911) | G37: 912 | H37: Fiction | I37: Drama | J37: 過渡 | K37: M | L37: 戯曲かつ綺堂の文体内変異（小説 vs 戯曲）の統制 | M37: 公開中 | O37: — | P37: 収録済
A38: 3 | B38: ジャンル | C38: 柳田国男 | D38: 遠野物語 | E38: 1910 | F38: 3_明治後期(1900-1911) | G38: 388 | H38: Nonfiction | I38: Ethnography | J38: 文語 | K38: M | L38: 民俗誌。学術散文という未収録のジャンル | M38: 公開中 | O38: — | P38: 収録済
... A42: 3 | B42: ジャンル | C42: 菊池寛 | D42: 父帰る | E42: 1917 | F42: 4_大正(1912-1925) | G42: 912 | H42: Fiction | I42: Drama | J42: 口語 | K42: M | L42: 戯曲。現行コーパスにゼロ。会話文比率の極値として重要 | M42: 公開中 | O42: — | P42: 収録済
A43: 3 | B43: ジャンル | C43: 岸田国士 | D43: 紙風船 | E43: 1925 | F43: 4_大正(1912-1925) | G43: 912 | H43: Fiction | I43: Drama | J43: 口語 | K43: M | L43: 大正期の口語戯曲 | M43: 要改称 | N43: 52082 | O43: 正式な作品名は『紙風船（一幕）』。NDC 912、新字旧仮名、初出1925年 | P43: 収録済
...

Sheet codebook
A1: 列名 | B1: 説明 | C1: 統制語彙
A2: id | B2: 作品の一意識別子。JLIT001–064。以後この ID で参照する
A3: file_v1 | B3: v1 コーパスにおけるファイル名（対応確認用）
A4: author_ja / author_reading / author_sex / author_birth / author_death | B4: 著者情報。sex は F / M
A5: title_aozora | B5: 青空文庫の作品名欄どおりの表記。v1 の通称ではなくこちらを正とする
A6: aozora_person_id / aozora_work_id / aozora_card_url | B6: 青空文庫の人物 ID・作品 ID・図書カード URL。再取得と検証の鍵
A7: year_first / year_first_end | B7: 初出の開始年と終了年。単発なら同値
A8: year_source | B8: card＝青空文庫図書カードの記載どおり／editor＝カードに記載がなく編者が補った。editor 行は要確認 | C8: card / editor
A9: period | B9: 初出年の文学史的区分（6区分） | C9: 1_明治前期 / 2_明治中期 / 3_明治後期 / 4_大正 / 5_昭和戦前 / 6_昭和戦後
A10: ndc / ndc_label | B10: NDC 番号とその日本語ラベル。K 接頭辞は児童書 | C10: 913 / K913 / 914 / 915 / 289 / 370 / 180
A11: genre_main | B11: 第1層ジャンル | C11: Fiction / Nonfiction
A12: genre_sub | B12: 第2層ジャンル（統制語彙） | C12: Modern, Historical, Detective, Ghost-Story, SF, Juvenile-SF, Juvenile-Mystery, Proletarian, Naturalist, Bildungsroman, Melodrama, Aesthetic, Experimental, Detective-Edo, Historical-Fantasy, Historical-Biography, Autobiography, Autobiographical-Diary, Diary, Criticism, Sketch-Essay, Enlightenment-Didactic, Religious-Didactic
A13: form | B13: テクストの形態 | C13: novel / novella / short-story / collection / cycle / essay / treatise / biography / autobiography / diary / diary-novel
A14: audience | B14: 想定読者 | C14: general / juvenile
A15: register_level | B15: 文化的位置づけ。v1 の brow を置き換える | C15: canonical / middlebrow / popular / documentary
A16: narration | B16: 語りの視点 | C16: first（一人称）/ third（三人称）/ mixed（作品内で交替・枠物語）/ dialogue（対話体）/ none（非物語）
A17: first_medium | B17: 初出媒体 | C17: newspaper / magazine / book
A18: kana_orthography | B18: 青空文庫の文字遣い種別 | C18: 新字新仮名 / 新字旧仮名 / 旧字旧仮名
A19: completeness | B19: テクストの完全性 | C19: complete / incomplete（原作が未完）/ part（分冊の一冊）/ PARTIAL（一部のみ収録）/ revised（改稿版）/ superseded（v1 の合本。分冊で取り直したので集計から外す）/ DUPLICATE（本文の取り違え）
... A21: bungo_ratio | B21: 文語標識が文語・口語標識全体に占める割合。0（純口語）〜1（純文語） | C21: style_class の判定根拠。閾値を変えるならこの列で確かめる
A22: tokens / types / ttr_x1000 | B22: v1 の分かち書きテクストにおける延べ語数・異なり語数・TTR×1000。※再構築後に更新すること
A23: kanji_ratio / katakana_ratio | B23: 非空白文字に占める漢字・片仮名の比率
A24: bungo_per10k / kogo_per10k | B24: 文語助動詞標識・口語助動詞標識の頻度。**1万語あたり**（10000×該当語数÷総語数）であって per million ではない。複合形（である＝で＋ある）も連結して数える
A25: p1_per10k / p3_per10k | B25: 一人称代名詞・三人称代名詞の**1万語あたり**頻度（narration の裏付け）
A26: gaiji_lost | B26: 本文に残存する ※ の数＝失われた外字の数。0 でないものは要再構築
A27: kana_odoriji / kanji_odoriji / ditto_mark | B27: 仮名踊り字（ゝゞヽヾ）・漢字踊り字（々）・同上記号（〃）の数
A28: latin_chars / arabic_digits | B28: ラテン文字数・算用数字数。表記正規化の対象量
A29: note | B29: 作品固有の注記。【重大】【修正】で始まるものは対応必須
